python script.py 
Traceback (most recent call last):
  File "/usr/local/lib/python3.9/dist-packages/PyBluez-0.30-py3.9-linux-aarch64.egg/bluetooth/bluez.py", line 271, in advertise_service
_bluetooth.error: no advertisable device

During handling of the above exception, another exception occurred:

Traceback (most recent call last):
  File "/home/admin/Desktop/SmartMirror/PyBluez/script.py", line 33, in <module>
    bluetooth.advertise_service(
  File "/usr/local/lib/python3.9/dist-packages/PyBluez-0.30-py3.9-linux-aarch64.egg/bluetooth/bluez.py", line 275, in advertise_service
bluetooth.btcommon.BluetoothError: no advertisable device
